npm WARN config global `--global`, `--local` are deprecated. Use `--location=global` instead.

> dev
> vite


  VITE v3.0.7  ready in 1151 ms

  ➜  Local:   http://127.0.0.1:3000/static/
X [ERROR] [plugin vite:dep-pre-bundle] Failed to resolve entry for package "function-bind". The package may have incorrect main/module/exports specified in its package.json.

    node_modules/esbuild/lib/main.js:933:27:
      933 │               let result = await callback2({
          ╵                            ^

    at packageEntryFailure (file:///D:/Projects/Python/demo_inertia_django/node_modules/vite/dist/node/chunks/dep-0f13c890.js:34419:11)
    at resolvePackageEntry (file:///D:/Projects/Python/demo_inertia_django/node_modules/vite/dist/node/chunks/dep-0f13c890.js:34416:5)
    at tryNodeResolve (file:///D:/Projects/Python/demo_inertia_django/node_modules/vite/dist/node/chunks/dep-0f13c890.js:34165:20)
    at Context.resolveId (file:///D:/Projects/Python/demo_inertia_django/node_modules/vite/dist/node/chunks/dep-0f13c890.js:33967:28)
    at Object.resolveId (file:///D:/Projects/Python/demo_inertia_django/node_modules/vite/dist/node/chunks/dep-0f13c890.js:35225:55)
    at processTicksAndRejections (node:internal/process/task_queues:96:5)
    at async file:///D:/Projects/Python/demo_inertia_django/node_modules/vite/dist/node/chunks/dep-0f13c890.js:62687:21      
    at async file:///D:/Projects/Python/demo_inertia_django/node_modules/vite/dist/node/chunks/dep-0f13c890.js:34682:34      
    at async callback (D:\Projects\Python\demo_inertia_django\node_modules\esbuild\lib\main.js:933:28)
    at async handleRequest (D:\Projects\Python\demo_inertia_django\node_modules\esbuild\lib\main.js:713:30)

  This error came from the "onResolve" callback registered here:

    node_modules/esbuild/lib/main.js:855:22:
      855 │         let promise = setup({
          ╵                       ^

    at setup (file:///D:/Projects/Python/demo_inertia_django/node_modules/vite/dist/node/chunks/dep-0f13c890.js:34662:19)    
    at handlePlugins (D:\Projects\Python\demo_inertia_django\node_modules\esbuild\lib\main.js:855:23)
    at Object.buildOrServe (D:\Projects\Python\demo_inertia_django\node_modules\esbuild\lib\main.js:1149:7)
    at D:\Projects\Python\demo_inertia_django\node_modules\esbuild\lib\main.js:2110:17
    at new Promise (<anonymous>)
    at Object.build (D:\Projects\Python\demo_inertia_django\node_modules\esbuild\lib\main.js:2109:14)
    at build (D:\Projects\Python\demo_inertia_django\node_modules\esbuild\lib\main.js:1956:51)
    at runOptimizeDeps (file:///D:/Projects/Python/demo_inertia_django/node_modules/vite/dist/node/chunks/dep-0f13c890.js:36953:26)
    at processTicksAndRejections (node:internal/process/task_queues:96:5)

  The plugin "vite:dep-pre-bundle" was triggered by this import

    node_modules/get-intrinsic/index.js:199:19:
      199 │ var bind = require('function-bind');
          ╵                    ~~~~~~~~~~~~~~~

X [ERROR] [plugin vite:dep-pre-bundle] Failed to resolve entry for package "function-bind". The package may have incorrect main/module/exports specified in its package.json.

    node_modules/esbuild/lib/main.js:933:27:
      933 │               let result = await callback2({
          ╵                            ^

    at packageEntryFailure (file:///D:/Projects/Python/demo_inertia_django/node_modules/vite/dist/node/chunks/dep-0f13c890.js:34419:11)
    at resolvePackageEntry (file:///D:/Projects/Python/demo_inertia_django/node_modules/vite/dist/node/chunks/dep-0f13c890.js:34416:5)
    at tryNodeResolve (file:///D:/Projects/Python/demo_inertia_django/node_modules/vite/dist/node/chunks/dep-0f13c890.js:34165:20)
    at Context.resolveId (file:///D:/Projects/Python/demo_inertia_django/node_modules/vite/dist/node/chunks/dep-0f13c890.js:33967:28)
    at Object.resolveId (file:///D:/Projects/Python/demo_inertia_django/node_modules/vite/dist/node/chunks/dep-0f13c890.js:35225:55)
    at processTicksAndRejections (node:internal/process/task_queues:96:5)
    at async file:///D:/Projects/Python/demo_inertia_django/node_modules/vite/dist/node/chunks/dep-0f13c890.js:62687:21      
    at async file:///D:/Projects/Python/demo_inertia_django/node_modules/vite/dist/node/chunks/dep-0f13c890.js:34682:34      
    at async callback (D:\Projects\Python\demo_inertia_django\node_modules\esbuild\lib\main.js:933:28)
    at async handleRequest (D:\Projects\Python\demo_inertia_django\node_modules\esbuild\lib\main.js:713:30)

  This error came from the "onResolve" callback registered here:

    node_modules/esbuild/lib/main.js:855:22:
      855 │         let promise = setup({
          ╵                       ^

    at setup (file:///D:/Projects/Python/demo_inertia_django/node_modules/vite/dist/node/chunks/dep-0f13c890.js:34662:19)    
    at handlePlugins (D:\Projects\Python\demo_inertia_django\node_modules\esbuild\lib\main.js:855:23)
    at Object.buildOrServe (D:\Projects\Python\demo_inertia_django\node_modules\esbuild\lib\main.js:1149:7)
    at D:\Projects\Python\demo_inertia_django\node_modules\esbuild\lib\main.js:2110:17
    at new Promise (<anonymous>)
    at Object.build (D:\Projects\Python\demo_inertia_django\node_modules\esbuild\lib\main.js:2109:14)
    at build (D:\Projects\Python\demo_inertia_django\node_modules\esbuild\lib\main.js:1956:51)
    at runOptimizeDeps (file:///D:/Projects/Python/demo_inertia_django/node_modules/vite/dist/node/chunks/dep-0f13c890.js:36953:26)
    at processTicksAndRejections (node:internal/process/task_queues:96:5)

  The plugin "vite:dep-pre-bundle" was triggered by this import

    node_modules/call-bind/index.js:3:19:
      3 │ var bind = require('function-bind');
        ╵                    ~~~~~~~~~~~~~~~

X [ERROR] [plugin vite:dep-pre-bundle] Failed to resolve entry for package "has". The package may have incorrect main/module/exports specified in its package.json.

    node_modules/esbuild/lib/main.js:933:27:
      933 │               let result = await callback2({
          ╵                            ^

    at packageEntryFailure (file:///D:/Projects/Python/demo_inertia_django/node_modules/vite/dist/node/chunks/dep-0f13c890.js:34419:11)
    at resolvePackageEntry (file:///D:/Projects/Python/demo_inertia_django/node_modules/vite/dist/node/chunks/dep-0f13c890.js:34416:5)
    at tryNodeResolve (file:///D:/Projects/Python/demo_inertia_django/node_modules/vite/dist/node/chunks/dep-0f13c890.js:34165:20)
    at Context.resolveId (file:///D:/Projects/Python/demo_inertia_django/node_modules/vite/dist/node/chunks/dep-0f13c890.js:33967:28)
    at Object.resolveId (file:///D:/Projects/Python/demo_inertia_django/node_modules/vite/dist/node/chunks/dep-0f13c890.js:35225:55)
    at processTicksAndRejections (node:internal/process/task_queues:96:5)
    at async file:///D:/Projects/Python/demo_inertia_django/node_modules/vite/dist/node/chunks/dep-0f13c890.js:62687:21      
    at async file:///D:/Projects/Python/demo_inertia_django/node_modules/vite/dist/node/chunks/dep-0f13c890.js:34682:34      
    at async callback (D:\Projects\Python\demo_inertia_django\node_modules\esbuild\lib\main.js:933:28)
    at async handleRequest (D:\Projects\Python\demo_inertia_django\node_modules\esbuild\lib\main.js:713:30)

  This error came from the "onResolve" callback registered here:

    node_modules/esbuild/lib/main.js:855:22:
      855 │         let promise = setup({
          ╵                       ^

    at setup (file:///D:/Projects/Python/demo_inertia_django/node_modules/vite/dist/node/chunks/dep-0f13c890.js:34662:19)    
    at handlePlugins (D:\Projects\Python\demo_inertia_django\node_modules\esbuild\lib\main.js:855:23)
    at Object.buildOrServe (D:\Projects\Python\demo_inertia_django\node_modules\esbuild\lib\main.js:1149:7)
    at D:\Projects\Python\demo_inertia_django\node_modules\esbuild\lib\main.js:2110:17
    at new Promise (<anonymous>)
    at Object.build (D:\Projects\Python\demo_inertia_django\node_modules\esbuild\lib\main.js:2109:14)
    at build (D:\Projects\Python\demo_inertia_django\node_modules\esbuild\lib\main.js:1956:51)
    at runOptimizeDeps (file:///D:/Projects/Python/demo_inertia_django/node_modules/vite/dist/node/chunks/dep-0f13c890.js:36953:26)
    at processTicksAndRejections (node:internal/process/task_queues:96:5)

  The plugin "vite:dep-pre-bundle" was triggered by this import

    node_modules/get-intrinsic/index.js:200:21:
      200 │ var hasOwn = require('has');
          ╵                      ~~~~~

D:\Projects\Python\demo_inertia_django\node_modules\esbuild\lib\main.js:1624
  let error = new Error(`${text}${summary}`);
              ^

Error: Build failed with 3 errors:
node_modules/esbuild/lib/main.js:933:27: ERROR: [plugin: vite:dep-pre-bundle] Failed to resolve entry for package "function-bind". The package may have incorrect main/module/exports specified in its package.json.
node_modules/esbuild/lib/main.js:933:27: ERROR: [plugin: vite:dep-pre-bundle] Failed to resolve entry for package "function-bind". The package may have incorrect main/module/exports specified in its package.json.
node_modules/esbuild/lib/main.js:933:27: ERROR: [plugin: vite:dep-pre-bundle] Failed to resolve entry for package "has". The 
package may have incorrect main/module/exports specified in its package.json.
    at failureErrorWithLog (D:\Projects\Python\demo_inertia_django\node_modules\esbuild\lib\main.js:1624:15)
    at D:\Projects\Python\demo_inertia_django\node_modules\esbuild\lib\main.js:1266:28
    at runOnEndCallbacks (D:\Projects\Python\demo_inertia_django\node_modules\esbuild\lib\main.js:1046:63)
    at buildResponseToResult (D:\Projects\Python\demo_inertia_django\node_modules\esbuild\lib\main.js:1264:7)
    at D:\Projects\Python\demo_inertia_django\node_modules\esbuild\lib\main.js:1377:14
    at D:\Projects\Python\demo_inertia_django\node_modules\esbuild\lib\main.js:678:9
    at handleIncomingPacket (D:\Projects\Python\demo_inertia_django\node_modules\esbuild\lib\main.js:775:9)
    at Socket.readFromStdout (D:\Projects\Python\demo_inertia_django\node_modules\esbuild\lib\main.js:644:7)
    at Socket.emit (node:events:527:28)
    at addChunk (node:internal/streams/readable:315:12) {
  errors: [
    {
      detail: Error: Failed to resolve entry for package "function-bind". The package may have incorrect main/module/exports 
specified in its package.json.
          at packageEntryFailure (file:///D:/Projects/Python/demo_inertia_django/node_modules/vite/dist/node/chunks/dep-0f13c890.js:34419:11)
          at resolvePackageEntry (file:///D:/Projects/Python/demo_inertia_django/node_modules/vite/dist/node/chunks/dep-0f13c890.js:34416:5)
          at tryNodeResolve (file:///D:/Projects/Python/demo_inertia_django/node_modules/vite/dist/node/chunks/dep-0f13c890.js:34165:20)
          at Context.resolveId (file:///D:/Projects/Python/demo_inertia_django/node_modules/vite/dist/node/chunks/dep-0f13c890.js:33967:28)
          at Object.resolveId (file:///D:/Projects/Python/demo_inertia_django/node_modules/vite/dist/node/chunks/dep-0f13c890.js:35225:55)
          at processTicksAndRejections (node:internal/process/task_queues:96:5)
          at async file:///D:/Projects/Python/demo_inertia_django/node_modules/vite/dist/node/chunks/dep-0f13c890.js:62687:21          at async file:///D:/Projects/Python/demo_inertia_django/node_modules/vite/dist/node/chunks/dep-0f13c890.js:34682:34          at async callback (D:\Projects\Python\demo_inertia_django\node_modules\esbuild\lib\main.js:933:28)
          at async handleRequest (D:\Projects\Python\demo_inertia_django\node_modules\esbuild\lib\main.js:713:30),
      id: '',
      location: {
        column: 27,
        file: 'node_modules/esbuild/lib/main.js',
        length: 0,
        line: 933,
        lineText: '              let result = await callback2({\n' +
          '    at packageEntryFailure (file:///D:/Projects/Python/demo_inertia_django/node_modules/vite/dist/node/chunks/dep-0f13c890.js:34419:11)\n' +
          '    at resolvePackageEntry (file:///D:/Projects/Python/demo_inertia_django/node_modules/vite/dist/node/chunks/dep-0f13c890.js:34416:5)\n' +
          '    at tryNodeResolve (file:///D:/Projects/Python/demo_inertia_django/node_modules/vite/dist/node/chunks/dep-0f13c890.js:34165:20)\n' +
          '    at Context.resolveId (file:///D:/Projects/Python/demo_inertia_django/node_modules/vite/dist/node/chunks/dep-0f13c890.js:33967:28)\n' +
          '    at Object.resolveId (file:///D:/Projects/Python/demo_inertia_django/node_modules/vite/dist/node/chunks/dep-0f13c890.js:35225:55)\n' +
          '    at processTicksAndRejections (node:internal/process/task_queues:96:5)\n' +
          '    at async file:///D:/Projects/Python/demo_inertia_django/node_modules/vite/dist/node/chunks/dep-0f13c890.js:62687:21\n' +
          '    at async file:///D:/Projects/Python/demo_inertia_django/node_modules/vite/dist/node/chunks/dep-0f13c890.js:34682:34\n' +
          '    at async callback (D:\\Projects\\Python\\demo_inertia_django\\node_modules\\esbuild\\lib\\main.js:933:28)\n' +          '    at async handleRequest (D:\\Projects\\Python\\demo_inertia_django\\node_modules\\esbuild\\lib\\main.js:713:30)',
        namespace: 'file',
        suggestion: ''
      },
      notes: [
        {
          location: {
            column: 22,
            file: 'node_modules/esbuild/lib/main.js',
            length: 0,
            line: 855,
            lineText: '        let promise = setup({\n' +
              '    at setup (file:///D:/Projects/Python/demo_inertia_django/node_modules/vite/dist/node/chunks/dep-0f13c890.js:34662:19)\n' +
              '    at handlePlugins (D:\\Projects\\Python\\demo_inertia_django\\node_modules\\esbuild\\lib\\main.js:855:23)\n' +
              '    at Object.buildOrServe (D:\\Projects\\Python\\demo_inertia_django\\node_modules\\esbuild\\lib\\main.js:1149:7)\n' +
              '    at D:\\Projects\\Python\\demo_inertia_django\\node_modules\\esbuild\\lib\\main.js:2110:17\n' +
              '    at new Promise (<anonymous>)\n' +
              '    at Object.build (D:\\Projects\\Python\\demo_inertia_django\\node_modules\\esbuild\\lib\\main.js:2109:14)\n' +
              '    at build (D:\\Projects\\Python\\demo_inertia_django\\node_modules\\esbuild\\lib\\main.js:1956:51)\n' +    
              '    at runOptimizeDeps (file:///D:/Projects/Python/demo_inertia_django/node_modules/vite/dist/node/chunks/dep-0f13c890.js:36953:26)\n' +
              '    at processTicksAndRejections (node:internal/process/task_queues:96:5)',
            namespace: 'file',
            suggestion: ''
          },
          text: 'This error came from the "onResolve" callback registered here:'
        },
        {
          location: {
            column: 19,
            file: 'node_modules/get-intrinsic/index.js',
            length: 15,
            line: 199,
            lineText: "var bind = require('function-bind');",
            namespace: '',
            suggestion: ''
          },
          text: 'The plugin "vite:dep-pre-bundle" was triggered by this import'
        }
      ],
      pluginName: 'vite:dep-pre-bundle',
      text: 'Failed to resolve entry for package "function-bind". The package may have incorrect main/module/exports specified in its package.json.'
    },
    {
      detail: Error: Failed to resolve entry for package "function-bind". The package may have incorrect main/module/exports 
specified in its package.json.
          at packageEntryFailure (file:///D:/Projects/Python/demo_inertia_django/node_modules/vite/dist/node/chunks/dep-0f13c890.js:34419:11)
          at resolvePackageEntry (file:///D:/Projects/Python/demo_inertia_django/node_modules/vite/dist/node/chunks/dep-0f13c890.js:34416:5)
          at tryNodeResolve (file:///D:/Projects/Python/demo_inertia_django/node_modules/vite/dist/node/chunks/dep-0f13c890.js:34165:20)
          at Context.resolveId (file:///D:/Projects/Python/demo_inertia_django/node_modules/vite/dist/node/chunks/dep-0f13c890.js:33967:28)
          at Object.resolveId (file:///D:/Projects/Python/demo_inertia_django/node_modules/vite/dist/node/chunks/dep-0f13c890.js:35225:55)
          at processTicksAndRejections (node:internal/process/task_queues:96:5)
          at async file:///D:/Projects/Python/demo_inertia_django/node_modules/vite/dist/node/chunks/dep-0f13c890.js:62687:21          at async file:///D:/Projects/Python/demo_inertia_django/node_modules/vite/dist/node/chunks/dep-0f13c890.js:34682:34          at async callback (D:\Projects\Python\demo_inertia_django\node_modules\esbuild\lib\main.js:933:28)
          at async handleRequest (D:\Projects\Python\demo_inertia_django\node_modules\esbuild\lib\main.js:713:30),
      id: '',
      location: {
        column: 27,
        file: 'node_modules/esbuild/lib/main.js',
        length: 0,
        line: 933,
        lineText: '              let result = await callback2({\n' +
          '    at packageEntryFailure (file:///D:/Projects/Python/demo_inertia_django/node_modules/vite/dist/node/chunks/dep-0f13c890.js:34419:11)\n' +
          '    at resolvePackageEntry (file:///D:/Projects/Python/demo_inertia_django/node_modules/vite/dist/node/chunks/dep-0f13c890.js:34416:5)\n' +
          '    at tryNodeResolve (file:///D:/Projects/Python/demo_inertia_django/node_modules/vite/dist/node/chunks/dep-0f13c890.js:34165:20)\n' +
          '    at Context.resolveId (file:///D:/Projects/Python/demo_inertia_django/node_modules/vite/dist/node/chunks/dep-0f13c890.js:33967:28)\n' +
          '    at Object.resolveId (file:///D:/Projects/Python/demo_inertia_django/node_modules/vite/dist/node/chunks/dep-0f13c890.js:35225:55)\n' +
          '    at processTicksAndRejections (node:internal/process/task_queues:96:5)\n' +
          '    at async file:///D:/Projects/Python/demo_inertia_django/node_modules/vite/dist/node/chunks/dep-0f13c890.js:62687:21\n' +
          '    at async file:///D:/Projects/Python/demo_inertia_django/node_modules/vite/dist/node/chunks/dep-0f13c890.js:34682:34\n' +
          '    at async callback (D:\\Projects\\Python\\demo_inertia_django\\node_modules\\esbuild\\lib\\main.js:933:28)\n' +          '    at async handleRequest (D:\\Projects\\Python\\demo_inertia_django\\node_modules\\esbuild\\lib\\main.js:713:30)',
        namespace: 'file',
        suggestion: ''
      },
      notes: [
        {
          location: {
            column: 22,
            file: 'node_modules/esbuild/lib/main.js',
            length: 0,
            line: 855,
            lineText: '        let promise = setup({\n' +
              '    at setup (file:///D:/Projects/Python/demo_inertia_django/node_modules/vite/dist/node/chunks/dep-0f13c890.js:34662:19)\n' +
              '    at handlePlugins (D:\\Projects\\Python\\demo_inertia_django\\node_modules\\esbuild\\lib\\main.js:855:23)\n' +
              '    at Object.buildOrServe (D:\\Projects\\Python\\demo_inertia_django\\node_modules\\esbuild\\lib\\main.js:1149:7)\n' +
              '    at D:\\Projects\\Python\\demo_inertia_django\\node_modules\\esbuild\\lib\\main.js:2110:17\n' +
              '    at new Promise (<anonymous>)\n' +
              '    at Object.build (D:\\Projects\\Python\\demo_inertia_django\\node_modules\\esbuild\\lib\\main.js:2109:14)\n' +
              '    at build (D:\\Projects\\Python\\demo_inertia_django\\node_modules\\esbuild\\lib\\main.js:1956:51)\n' +    
              '    at runOptimizeDeps (file:///D:/Projects/Python/demo_inertia_django/node_modules/vite/dist/node/chunks/dep-0f13c890.js:36953:26)\n' +
              '    at processTicksAndRejections (node:internal/process/task_queues:96:5)',
            namespace: 'file',
            suggestion: ''
          },
          text: 'This error came from the "onResolve" callback registered here:'
        },
        {
          location: {
            column: 19,
            file: 'node_modules/call-bind/index.js',
            length: 15,
            line: 3,
            lineText: "var bind = require('function-bind');",
            namespace: '',
            suggestion: ''
          },
          text: 'The plugin "vite:dep-pre-bundle" was triggered by this import'
        }
      ],
      pluginName: 'vite:dep-pre-bundle',
      text: 'Failed to resolve entry for package "function-bind". The package may have incorrect main/module/exports specified in its package.json.'
    },
    {
      detail: Error: Failed to resolve entry for package "has". The package may have incorrect main/module/exports specified 
in its package.json.
          at packageEntryFailure (file:///D:/Projects/Python/demo_inertia_django/node_modules/vite/dist/node/chunks/dep-0f13c890.js:34419:11)
          at resolvePackageEntry (file:///D:/Projects/Python/demo_inertia_django/node_modules/vite/dist/node/chunks/dep-0f13c890.js:34416:5)
          at tryNodeResolve (file:///D:/Projects/Python/demo_inertia_django/node_modules/vite/dist/node/chunks/dep-0f13c890.js:34165:20)
          at Context.resolveId (file:///D:/Projects/Python/demo_inertia_django/node_modules/vite/dist/node/chunks/dep-0f13c890.js:33967:28)
          at Object.resolveId (file:///D:/Projects/Python/demo_inertia_django/node_modules/vite/dist/node/chunks/dep-0f13c890.js:35225:55)
          at processTicksAndRejections (node:internal/process/task_queues:96:5)
          at async file:///D:/Projects/Python/demo_inertia_django/node_modules/vite/dist/node/chunks/dep-0f13c890.js:62687:21          at async file:///D:/Projects/Python/demo_inertia_django/node_modules/vite/dist/node/chunks/dep-0f13c890.js:34682:34          at async callback (D:\Projects\Python\demo_inertia_django\node_modules\esbuild\lib\main.js:933:28)
          at async handleRequest (D:\Projects\Python\demo_inertia_django\node_modules\esbuild\lib\main.js:713:30),
      id: '',
      location: {
        column: 27,
        file: 'node_modules/esbuild/lib/main.js',
        length: 0,
        line: 933,
        lineText: '              let result = await callback2({\n' +
          '    at packageEntryFailure (file:///D:/Projects/Python/demo_inertia_django/node_modules/vite/dist/node/chunks/dep-0f13c890.js:34419:11)\n' +
          '    at resolvePackageEntry (file:///D:/Projects/Python/demo_inertia_django/node_modules/vite/dist/node/chunks/dep-0f13c890.js:34416:5)\n' +
          '    at tryNodeResolve (file:///D:/Projects/Python/demo_inertia_django/node_modules/vite/dist/node/chunks/dep-0f13c890.js:34165:20)\n' +
          '    at Context.resolveId (file:///D:/Projects/Python/demo_inertia_django/node_modules/vite/dist/node/chunks/dep-0f13c890.js:33967:28)\n' +
          '    at Object.resolveId (file:///D:/Projects/Python/demo_inertia_django/node_modules/vite/dist/node/chunks/dep-0f13c890.js:35225:55)\n' +
          '    at processTicksAndRejections (node:internal/process/task_queues:96:5)\n' +
          '    at async file:///D:/Projects/Python/demo_inertia_django/node_modules/vite/dist/node/chunks/dep-0f13c890.js:62687:21\n' +
          '    at async file:///D:/Projects/Python/demo_inertia_django/node_modules/vite/dist/node/chunks/dep-0f13c890.js:34682:34\n' +
          '    at async callback (D:\\Projects\\Python\\demo_inertia_django\\node_modules\\esbuild\\lib\\main.js:933:28)\n' +          '    at async handleRequest (D:\\Projects\\Python\\demo_inertia_django\\node_modules\\esbuild\\lib\\main.js:713:30)',
        namespace: 'file',
        suggestion: ''
      },
      notes: [
        {
          location: {
            column: 22,
            file: 'node_modules/esbuild/lib/main.js',
            length: 0,
            line: 855,
            lineText: '        let promise = setup({\n' +
              '    at setup (file:///D:/Projects/Python/demo_inertia_django/node_modules/vite/dist/node/chunks/dep-0f13c890.js:34662:19)\n' +
              '    at handlePlugins (D:\\Projects\\Python\\demo_inertia_django\\node_modules\\esbuild\\lib\\main.js:855:23)\n' +
              '    at Object.buildOrServe (D:\\Projects\\Python\\demo_inertia_django\\node_modules\\esbuild\\lib\\main.js:1149:7)\n' +
              '    at D:\\Projects\\Python\\demo_inertia_django\\node_modules\\esbuild\\lib\\main.js:2110:17\n' +
              '    at new Promise (<anonymous>)\n' +
              '    at Object.build (D:\\Projects\\Python\\demo_inertia_django\\node_modules\\esbuild\\lib\\main.js:2109:14)\n' +
              '    at build (D:\\Projects\\Python\\demo_inertia_django\\node_modules\\esbuild\\lib\\main.js:1956:51)\n' +    
              '    at runOptimizeDeps (file:///D:/Projects/Python/demo_inertia_django/node_modules/vite/dist/node/chunks/dep-0f13c890.js:36953:26)\n' +
              '    at processTicksAndRejections (node:internal/process/task_queues:96:5)',
            namespace: 'file',
            suggestion: ''
          },
          text: 'This error came from the "onResolve" callback registered here:'
        },
        {
          location: {
            column: 21,
            file: 'node_modules/get-intrinsic/index.js',
            length: 5,
            line: 200,
            lineText: "var hasOwn = require('has');",
            namespace: '',
            suggestion: ''
          },
          text: 'The plugin "vite:dep-pre-bundle" was triggered by this import'
        }
      ],
      pluginName: 'vite:dep-pre-bundle',
      text: 'Failed to resolve entry for package "has". The package may have incorrect main/module/exports specified in its package.json.'
    }
  ],
  warnings: []
}